<?xml version="1.0" encoding="utf-8"?>
<!-- This URDF was automatically created by SolidWorks to URDF Exporter! Originally created by Stephen Brawner (brawner@gmail.com) 
     Commit Version: 1.5.1-0-g916b5db  Build Version: 1.5.7152.31018
     For more information, please see http://wiki.ros.org/sw_urdf_exporter -->
<robot name="watchdog">

  <gazebo reference = "base_link">
    <visual>
      <material>
        <ambient>0 0 0 1.0</ambient>
      </material>
    </visual>
  </gazebo>

  <gazebo reference = "Lidar_Link">
    <visual>
      <material>
        <ambient>0.25 0.25 0.25 1.0</ambient>
      </material>
    </visual>
  </gazebo>

  <gazebo reference = "LeWheel_Link">
    <visual>
      <material>
        <ambient>0 0.3 0.7 1.0</ambient>
      </material>
    </visual>
  </gazebo>

  <gazebo reference = "RiWheel_Link">
    <visual>
      <material>
	<ambient>0 0.3 0.7 1.0</ambient>
      </material>
    </visual>
  </gazebo>

  <gazebo reference = "LeMotor_Link">
    <visual>
      <material>
	<ambient>0.79 0.82 0.93 1.0</ambient>
      </material>
    </visual>
  </gazebo>

  <gazebo reference = "RiMotor_Link">
    <visual>
      <material>
	<ambient>0.79 0.82 0.93 1.0</ambient>
      </material>
    </visual>
  </gazebo>

  <gazebo reference = "Rasp_Link">
    <visual>
      <material>
	<ambient>1 0.5 0 1.0</ambient>
      </material>
    </visual>
  </gazebo>

  <gazebo reference = "Battery_Link">
    <visual>
      <material>
	<ambient>0 0.3 0.7 1.0</ambient>
      </material>
    </visual>
  </gazebo>

  <gazebo reference = "FreeWheel_Link">
    <visual>
      <material>
	<ambient>0.79 0.82 0.93 1.0</ambient>
      </material>
    </visual>
  </gazebo>

  <gazebo>
    <plugin name="differential_drive_controller" filename="libgazebo_ros_diff_drive.so">
      <!-- Plugin update rate in Hz -->
      <updateRate>20</updateRate>
      <!-- Name of left joint, defaults to `left_joint` -->
      <leftJoint>LeWheel_Joint</leftJoint>
      <!-- Name of right joint, defaults to `right_joint` -->
      <rightJoint>RiWheel_Joint</rightJoint>
      <!-- The distance from the center of one wheel to the other, in meters, defaults to 0.34 m -->
      <wheelSeparation>0.222</wheelSeparation>
      <!-- Diameter of the wheels, in meters, defaults to 0.15 m -->
      <wheelDiameter>0.101</wheelDiameter>
      <!-- Wheel acceleration, in rad/s^2, defaults to 0.0 rad/s^2 -->
      <wheelAcceleration>1.0</wheelAcceleration>
      <!-- Maximum torque which the wheels can produce, in Nm, defaults to 5 Nm -->
      <wheelTorque>5</wheelTorque>
      <!-- Topic to receive geometry_msgs/Twist message commands, defaults to `cmd_vel` -->
      <commandTopic>cmd_vel</commandTopic>
      <!-- Topic to publish nav_msgs/Odometry messages, defaults to `odom` -->
      <odometryTopic>odom</odometryTopic>
      <!-- Odometry frame, defaults to `odom` -->
      <odometryFrame>odom</odometryFrame>
      <!-- Robot frame to calculate odometry from, defaults to `base_footprint` -->
      <robotBaseFrame>base_link</robotBaseFrame>
      <!-- Odometry source, 0 for ENCODER, 1 for WORLD, defaults to WORLD -->
      <odometrySource>1</odometrySource>
      <!-- Set to true to publish transforms for the wheel links, defaults to false -->
      <publishWheelTF>true</publishWheelTF>
      <!-- Set to true to publish transforms for the odometry, defaults to true -->
      <publishOdom>true</publishOdom>
      <!-- Set to true to publish tf transform for the odometry -->
      <publishOdomTF>true</publishOdomTF>
      <!-- Set to true to publish sensor_msgs/JointState on /joint_states for the wheel joints, defaults to false -->
      <publishWheelJointState>true</publishWheelJointState>
      <!-- Set to true to swap right and left wheels, defaults to true -->
      <legacyMode>false</legacyMode>
      <rosDebugLevel>na</rosDebugLevel>
      <publishTf>true</publishTf>
    </plugin>
  </gazebo>

    <!-- hokuyo -->
  <gazebo reference="Lidar_Link">
    <sensor type="ray" name="head_hokuyo_sensor">
      <pose>0 0 0 0 0 0</pose>
      <visualize>false</visualize>
      <update_rate>7.69</update_rate>
      <ray>
	<scan>
	  <horizontal>
	    <samples>360</samples>
	    <resolution>1</resolution>
	    <min_angle>-3.1416</min_angle>
	    <max_angle>3.1416</max_angle>
	  </horizontal>
	</scan>
	<range>
	  <min>0.15</min>
	  <max>12.0</max>
	  <resolution>0.01</resolution>
	</range>
	<noise>
	  <type>gaussian</type>
	  <!-- Noise parameters based on published spec for Hokuyo laser
	  achieving "+-30mm" accuracy at range < 10m.  A mean of 0.0m and
          stddev of 0.01m will put 99.7% of samples within 0.03m of the true
	  reading. -->
	  <mean>0.0</mean>
	  <stddev>0.01</stddev>
	</noise>
      </ray>
      <plugin name="gazebo_ros_head_hokuyo_controller" filename="libgazebo_ros_laser.so">
	<topicName>/scan</topicName>
	<frameName>Lidar_Link</frameName>
      </plugin>
    </sensor>
  </gazebo>


  <link name="base_link">
    <inertial>
      <origin xyz="0.131936538447687 1.10553634065889E-06 0.0291518597123195" rpy="0 0 0" />
      <mass value="0.272802334634605" />
      <inertia
        ixx="0.000959804973774207"
        ixy="-2.50333273274752E-08"
        ixz="-4.350901863945E-05"
        iyy="0.0015886682926646"
        iyz="-5.05968513267232E-09"
        izz="0.0023886132736546" />
    </inertial>
    <visual>
      <origin xyz="0 0 0" rpy="0 0 0" />
      <geometry>
        <mesh filename="package://simulation_watchdog/meshes/base_link.STL" />
      </geometry>
      <material name="">
        <color rgba="0.2 0.2 0.2 1" />
      </material>
    </visual>
    <collision>
      <origin xyz="0 0 0" rpy="0 0 0" />
      <geometry>
        <mesh filename="package://simulation_watchdog/meshes/base_link.STL" />
      </geometry>
    </collision>
  </link>


  <link name="Lidar_Link">
    <inertial>
      <origin xyz="0.0119211686235004 -0.000829632077903888 -0.00986495283629452" rpy="0 0 0" />
      <mass value="0.0730824721237043" />
      <inertia
        ixx="1.95777683486533E-05"
        ixy="-4.51340417435688E-08"
        ixz="-4.28225037571919E-07"
        iyy="2.4127836575422E-05"
        iyz="1.51629263380133E-08"
        izz="4.14181727759423E-05" />
    </inertial>
    <visual>
      <origin xyz="0 0 0" rpy="0 0 0" />
      <geometry>
        <mesh filename="package://simulation_watchdog/meshes/Lidar_Link.STL" />
      </geometry>
      <material name="">
        <color rgba="0.45 0.45 0.45 1" />
      </material>
    </visual>
    <collision>
      <origin xyz="0 0 0" rpy="0 0 0" />
      <geometry>
        <mesh filename="package://simulation_watchdog/meshes/Lidar_Link.STL" />
      </geometry>
    </collision>
  </link>

  <joint name="Lidar_Joint" type="fixed">
    <origin xyz="0.0245950902140598 0.000353235794243532 0.0996000000000025" rpy="0 0 0" />
    <parent link="base_link" />
    <child link="Lidar_Link" />
    <axis xyz="0 0 0" />
  </joint>


  <link name="LeMotor_Link">
    <inertial>
      <origin xyz="-0.000125890117065902 -1.06776487074356E-06 -0.00800171182746318" rpy="0 0 0" />
      <mass value="0.0599050546017114" />
      <inertia
        ixx="2.60791206087044E-05"
        ixy="-4.4446147240325E-10"
        ixz="2.74140992935316E-07"
        iyy="2.61310804093162E-05"
        iyz="2.84653031957484E-09"
        izz="8.86042100272928E-06" />
    </inertial>
    <visual>
      <origin xyz="0 0 0" rpy="0 0 0" />
      <geometry>
        <mesh filename="package://simulation_watchdog/meshes/LeMotor_Link.STL" />
      </geometry>
      <material name="">
        <color rgba="0.79 0.82 0.93 1" />
      </material>
    </visual>
    <collision>
      <origin xyz="0 0 0" rpy="0 0 0" />
      <geometry>
        <mesh filename="package://simulation_watchdog/meshes/LeMotor_Link.STL" />
      </geometry>
    </collision>
  </link>

  <joint name="LeMotor_Joint" type="fixed">
    <origin xyz="0.00306359051227961 0.0585 0.00629399818662646" rpy="-1.5707963267949 -1.11780647710814 0" />
    <parent link="base_link" />
    <child link="LeMotor_Link" />
    <axis xyz="0 0 0" />
  </joint>


  <link name="LeWheel_Link">
    <inertial>
      <origin xyz="3.666E-06 -3.2357E-07 0.022928" rpy="0 0 0" />
      <mass value="0.15938" />
      <inertia
        ixx="9.5251E-05"
        ixy="-4.2873E-10"
        ixz="4.5264E-09"
        iyy="9.5247E-05"
        iyz="-3.9952E-10"
        izz="0.00017092" />
    </inertial>
    <visual>
      <origin xyz="0 0 0" rpy="0 0 0" />
      <geometry>
        <mesh filename="package://simulation_watchdog/meshes/LeWheel_Link.STL" />
      </geometry>
      <material name="">
        <color rgba="0 0.3 0.7 1" />
      </material>
    </visual>
    <collision>
      <origin xyz="0 0 0" rpy="0 0 0" />
      <geometry>
        <mesh filename="package://simulation_watchdog/meshes/LeWheel_Link.STL" />
      </geometry>
    </collision>
  </link>

  <joint name="LeWheel_Joint" type="continuous">
    <origin xyz="0 0.089 0" rpy="1.5708 0 3.1416" />
    <parent link="base_link" />
    <child link="LeWheel_Link" />
    <axis xyz="0 0 1" />
  </joint>


  <link name="RiMotor_Link">
    <inertial>
      <origin xyz="1.06776487074356E-06 -0.000125890117065902 -0.00800171182746318" rpy="0 0 0" />
      <mass value="0.0599050546017114" />
      <inertia
        ixx="2.61310804093162E-05"
        ixy="4.44461472399862E-10"
        ixz="-2.84653031957142E-09"
        iyy="2.60791206087044E-05"
        iyz="2.74140992935314E-07"
        izz="8.86042100272929E-06" />
    </inertial>
    <visual>
      <origin xyz="0 0 0" rpy="0 0 0" />
      <geometry>
        <mesh filename="package://simulation_watchdog/meshes/RiMotor_Link.STL" />
      </geometry>
      <material name="">
        <color rgba="0.79 0.82 0.93 1" />
      </material>
    </visual>
    <collision>
      <origin xyz="0 0 0" rpy="0 0 0" />
      <geometry>
        <mesh filename="package://simulation_watchdog/meshes/RiMotor_Link.STL" />
      </geometry>
    </collision>
  </link>

  <joint name="RiMotor_Joint" type="fixed">
    <origin xyz="0.00306359051226426 -0.0585 0.00629399818661908" rpy="1.5707963267949 0.452989849686705 0" />
    <parent link="base_link" />
    <child link="RiMotor_Link" />
    <axis xyz="0 0 0" />
  </joint>


  <link name="RiWheel_Link">
    <inertial>
      <origin xyz="-1.9338E-06 -3.1312E-06 -0.022928" rpy="0 0 0" />
      <mass value="0.15938" />
      <inertia
        ixx="9.5249E-05"
        ixy="1.5405E-09"
        ixz="2.3876E-09"
        iyy="9.5249E-05"
        iyz="3.8661E-09"
        izz="0.00017092" />
    </inertial>
    <visual>
      <origin xyz="0 0 0" rpy="0 0 0" />
      <geometry>
        <mesh filename="package://simulation_watchdog/meshes/RiWheel_Link.STL" />
      </geometry>
      <material name="">
        <color rgba="0 0.3 0.7 1" />
      </material>
    </visual>
    <collision>
      <origin xyz="0 0 0" rpy="0 0 0" />
      <geometry>
        <mesh filename="package://simulation_watchdog/meshes/RiWheel_Link.STL" />
      </geometry>
    </collision>
  </link>

  <joint name="RiWheel_Joint" type="continuous">
    <origin xyz="0 -0.089 0" rpy="1.5708 0.74603 3.1416" />
    <parent link="base_link" />
    <child link="RiWheel_Link" />
    <axis xyz="0 0 1" />
  </joint>


  <link name="Battery_Link">
    <inertial>
      <origin xyz="-7.95303784828505E-07 2.27409651937238E-06 0.0159926769522142" rpy="0 0 0" />
      <mass value="0.231124740264454" />
      <inertia
        ixx="6.95417445265297E-05"
        ixy="-1.09669422228662E-08"
        ixz="2.94290313071083E-09"
        iyy="0.000406525755701883"
        iyz="-8.38336036106287E-09"
        izz="0.000437193560344446" />
    </inertial>
    <visual>
      <origin xyz="0 0 0" rpy="0 0 0" />
      <geometry>
        <mesh filename="package://simulation_watchdog/meshes/Battery_Link.STL" />
      </geometry>
      <material name="">
        <color rgba="0 0.3 0.7 1" />
      </material>
    </visual>
    <collision>
      <origin xyz="0 0 0" rpy="0 0 0" />
      <geometry>
        <mesh filename="package://simulation_watchdog/meshes/Battery_Link.STL" />
      </geometry>
    </collision>
  </link>

  <joint name="Battery_Joint" type="fixed">
    <origin xyz="0.116500000000015 -0.04 0.0135000000000076" rpy="0 0 3.14159265358979" />
    <parent link="base_link" />
    <child link="Battery_Link" />
    <axis xyz="0 0 0" />
  </joint>


  <link name="MotoShield_Link">
    <inertial>
      <origin xyz="-0.000906663253647078 1.81987746071671E-05 0.00324859919524972" rpy="0 0 0" />
      <mass value="0.00965020666023458" />
      <inertia
        ixx="1.72879845391036E-06"
        ixy="2.95059873571204E-08"
        ixz="-2.04998086154079E-08"
        iyy="3.29786098239131E-06"
        iyz="-3.49996753867072E-10"
        izz="4.80689992233693E-06" />
    </inertial>
    <visual>
      <origin xyz="0 0 0" rpy="0 0 0" />
      <geometry>
        <mesh filename="package://simulation_watchdog/meshes/MotoShield_Link.STL" />
      </geometry>
      <material name="">
        <color rgba="0.792156862745098 0.819607843137255 0.933333333333333 1" />
      </material>
    </visual>
    <collision>
      <origin xyz="0 0 0" rpy="0 0 0" />
      <geometry>
        <mesh filename="package://simulation_watchdog/meshes/MotoShield_Link.STL" />
      </geometry>
    </collision>
  </link>

  <joint name="MotoShield_Joint" type="fixed">
    <origin xyz="0.087850000000015 0.04715 0.0135000000000076" rpy="0 0 3.14159265358979" />
    <parent link="base_link" />
    <child link="MotoShield_Link" />
    <axis xyz="0 0 0" />
  </joint>


  <link name="Rasp_Link">
    <inertial>
      <origin xyz="0.0597184603825512 0.0372848625782793 0.000466138543304295" rpy="0 0 0" />
      <mass value="0.0685167860703749" />
      <inertia
        ixx="2.53790376425816E-05"
        ixy="7.71182132417783E-09"
        ixz="7.17598630634175E-11"
        iyy="4.93580215384763E-05"
        iyz="2.92552324423039E-10"
        izz="7.40592965310709E-05" />
    </inertial>
    <visual>
      <origin xyz="0 0 0" rpy="0 0 0" />
      <geometry>
        <mesh filename="package://simulation_watchdog/meshes/Rasp_Link.STL" />
      </geometry>
      <material name="">
        <color rgba="1 0.67 0.23 1" />
      </material>
    </visual>
    <collision>
      <origin xyz="0 0 0" rpy="0 0 0" />
      <geometry>
        <mesh filename="package://simulation_watchdog/meshes/Rasp_Link.STL" />
      </geometry>
    </collision>
  </link>

  <joint name="Rasp_Joint" type="fixed">
    <origin xyz="0.215 0.05 0.07" rpy="0 0 3.14159265358979" />
    <parent link="base_link" />
    <child link="Rasp_Link" />
    <axis xyz="0 0 0" />
  </joint>


  <link name="FreeWheel_Link">
    <inertial>
      <origin xyz="0.000365289585873632 -0.000118819536407379 0.0104403397653149" rpy="0 0 0" />
      <mass value="0.0819906643957427" />
      <inertia
        ixx="2.33283423261154E-05"
        ixy="-1.24768892746176E-22"
        ixz="-5.13733916293795E-22"
        iyy="1.6590557819557E-05"
        iyz="-4.33783953061183E-22"
        izz="2.8648637026961E-05" />
    </inertial>
    <visual>
      <origin xyz="0 0 0" rpy="0 0 0" />
      <geometry>
        <mesh filename="package://simulation_watchdog/meshes/FreeWheel_Link.STL" />
      </geometry>
      <material name="">
        <color rgba="0.4 0.5 0.6 1" />
      </material>
    </visual>
    <collision>
      <origin xyz="0 0 0" rpy="0 0 0" />
      <geometry>
        <mesh filename="package://simulation_watchdog/meshes/FreeWheel_Link.STL" />
      </geometry>
    </collision>
  </link>

  <joint name="FreeWheel_Joint" type="fixed">
    <origin xyz="0.20537 -0.00011882 -0.02278" rpy="0 0 3.1416" />
    <parent link="base_link" />
    <child link="FreeWheel_Link" />
    <axis xyz="0 0 0" />
  </joint>

</robot>
